Workbook

Sheet Books
A1: Book ID | B1: Series | C1: Subject | D1: Grade | E1: Term | F1: Year | G1: Publisher | H1: Type | I1: Cover | J1: File | K1: Format | L1: Pages | M1: Paper Count | N1: Unit Price (EGP)
A2: 1 | B2: التأسيس | C2: رياضيات | D2: 1 | E2: 1 | F2: 2027 | G2: المتميزون | H2: كتاب | I2: Y | J2: library\Grade_01\التأسيس - رياضيات - الصف الأول الابتدائي - الترم الأول - 2027 - المتميزون - الصف الاول الابتدائي الصف الاول الابتدائي.pdf | K2: pdf | L2: 242 | M2: =ROUND(L2*Settings!$B$4,0) | N2: =ROUND(M2*Settings!$B$2+IF(I2="Y",Settings!$B$3,0),2)
A3: 2 | D3: 1 | E3: 1 | F3: 2027 | G3: المتميزون | H3: كتاب | I3: Y | J3: library\Grade_01\الصف الأول الابتدائي - الترم الأول - 2027 - المتميزون - الصف الاول الابتدائي الصف الاول الابتدائي سندباد رياضه.pdf | K3: pdf | L3: 288 | M3: =ROUND(L3*Settings!$B$4,0) | N3: =ROUND(M3*Settings!$B$2+IF(I3="Y",Settings!$B$3,0),2)
A4: 3 | C4: رياضيات | D4: 1 | E4: 1 | F4: 2027 | G4: المتميزون | H4: كتاب | I4: Y | J4: library\Grade_01\رياضيات - الصف الأول الابتدائي - الترم الأول - 2027 - المتميزون - الصف الاول الابتدائي الصف الاول الابتدائي الابرار.pdf | K4: pdf | L4: 301 | M4: =ROUND(L4*Settings!$B$4,0) | N4: =ROUND(M4*Settings!$B$2+IF(I4="Y",Settings!$B$3,0),2)
A5: 4 | C5: رياضيات | D5: 1 | E5: 1 | F5: 2027 | G5: المتميزون | H5: كتاب | I5: Y | J5: library\Grade_01\رياضيات - الصف الأول الابتدائي - الترم الأول - 2027 - المتميزون - الصف الاول الابتدائي الصف الاول الابتدائي قطر.pdf | K5: pdf | L5: 226 | M5: =ROUND(L5*Settings!$B$4,0) | N5: =ROUND(M5*Settings!$B$2+IF(I5="Y",Settings!$B$3,0),2)
A6: 5 | B6: سلاح التلميذ | D6: 1 | E6: 1 | F6: 2027 | G6: المتميزون | H6: كتاب | I6: Y | J6: library\Grade_01\سلاح التلميذ - الصف الأول الابتدائي - الترم الأول - 2027 - المتميزون - الصف الاول الابتدائي الصف الاول الابتدائي دين 1.pdf | K6: pdf | L6: 114 | M6: =ROUND(L6*Settings!$B$4,0) | N6: =ROUND(M6*Settings!$B$2+IF(I6="Y",Settings!$B$3,0),2)
A7: 6 | B7: سلاح التلميذ | C7: انجليزي | D7: 1 | E7: 1 | F7: 2027 | G7: المتميزون | H7: كتاب | I7: Y | J7: library\Grade_01\سلاح التلميذ - انجليزي - الصف الأول الابتدائي - الترم الأول - 2027 - المتميزون - الصف الاول الابتدائي الصف الاول الابتدائي.pdf | K7: pdf | L7: 274 | M7: =ROUND(L7*Settings!$B$4,0) | N7: =ROUND(M7*Settings!$B$2+IF(I7="Y",Settings!$B$3,0),2)
A8: 7 | B8: سلاح التلميذ | C8: رياضيات | D8: 1 | E8: 1 | F8: 2027 | G8: المتميزون | H8: كتاب | I8: Y | J8: library\Grade_01\سلاح التلميذ - رياضيات - الصف الأول الابتدائي - الترم الأول - 2027 - المتميزون - الصف الاول الابتدائي الصف الاول الابتدائي.pdf | K8: pdf | L8: 290 | M8: =ROUND(L8*Settings!$B$4,0) | N8: =ROUND(M8*Settings!$B$2+IF(I8="Y",Settings!$B$3,0),2)
A9: 8 | C9: عربي | D9: 1 | E9: 1 | F9: 2027 | G9: المتميزون | H9: كتاب | I9: Y | J9: library\Grade_01\عربي - الصف الأول الابتدائي - الترم الأول - 2027 - المتميزون - الصف الاول الابتدائي الصف الاول الابتدائي الابرار.pdf | K9: pdf | L9: 276 | M9: =ROUND(L9*Settings!$B$4,0) | N9: =ROUND(M9*Settings!$B$2+IF(I9="Y",Settings!$B$3,0),2)
A10: 9 | C10: عربي | D10: 1 | E10: 1 | F10: 2027 | G10: المتميزون | H10: كتاب | I10: Y | J10: library\Grade_01\عربي - الصف الأول الابتدائي - الترم الأول - 2027 - المتميزون - الصف الاول الابتدائي الصف الاول الابتدائي الاستاذ.pdf | K10: pdf | L10: 337 | M10: =ROUND(L10*Settings!$B$4,0) | N10: =ROUND(M10*Settings!$B$2+IF(I10="Y",Settings!$B$3,0),2)
A11: 10 | C11: عربي | D11: 1 | E11: 1 | F11: 2027 | G11: المتميزون | H11: كتاب | I11: Y | J11: library\Grade_01\عربي - الصف الأول الابتدائي - الترم الأول - 2027 - المتميزون - الصف الاول الابتدائي الصف الاول الابتدائي سندباد.pdf | K11: pdf | L11: 304 | M11: =ROUND(L11*Settings!$B$4,0) | N11: =ROUND(M11*Settings!$B$2+IF(I11="Y",Settings!$B$3,0),2)
A12: 11 | C12: عربي | D12: 1 | E12: 1 | F12: 2027 | G12: المتميزون | H12: كتاب | I12: Y | J12: library\Grade_01\عربي - الصف الأول الابتدائي - الترم الأول - 2027 - المتميزون - الصف الاول الابتدائي الصف الاول الابتدائي قطر.pdf | K12: pdf | L12: 282 | M12: =ROUND(L12*Settings!$B$4,0) | N12: =ROUND(M12*Settings!$B$2+IF(I12="Y",Settings!$B$3,0),2)
A13: 12 | B13: قطر الندى | D13: 1 | E13: 1 | F13: 2027 | G13: المتميزون | H13: كتاب | I13: Y | J13: library\Grade_01\قطر الندى - الصف الأول الابتدائي - الترم الأول - 2027 - المتميزون - الصف الاول الابتدائي الصف الاول الابتدائي دين.pdf | K13: pdf | L13: 98 | M13: =ROUND(L13*Settings!$B$4,0) | N13: =ROUND(M13*Settings!$B$2+IF(I13="Y",Settings!$B$3,0),2)
A14: 13 | B14: التأسيس | C14: رياضيات | D14: 1 | E14: 1 | F14: 2027 | G14: المتميزون | H14: ملحق | I14: Y | J14: library\Grade_01\ملحق التأسيس - رياضيات - الصف الأول الابتدائي - الترم الأول - 2027 - المتميزون - الصف الاول الابتدائي الصف الاول الابتدائي.pdf | K14: pdf | L14: 50 | M14: =ROUND(L14*Settings!$B$4,0) | N14: =ROUND(M14*Settings!$B$2+IF(I14="Y",Settings!$B$3,0),2)
A15: 14 | C15: عربي | D15: 1 | E15: 1 | F15: 2027 | G15: المتميزون | H15: ملحق | I15: Y | J15: library\Grade_01\ملحق عربي - الصف الأول الابتدائي - الترم الأول - 2027 - المتميزون - الصف الاول الابتدائي الصف الاول الابتدائي الاستاذ.pdf | K15: pdf | L15: 49 | M15: =ROUND(L15*Settings!$B$4,0) | N15: =ROUND(M15*Settings!$B$2+IF(I15="Y",Settings!$B$3,0),2)
A16: 15 | B16: الاضواء | C16: عربي | D16: 2 | E16: 1 | F16: 2027 | H16: كتاب | I16: Y | J16: library\Grade_02\الاضواء - عربي - الصف الثاني الابتدائي - الترم الأول - 2027.pdf | K16: pdf | L16: 288 | M16: =ROUND(L16*Settings!$B$4,0) | N16: =ROUND(M16*Settings!$B$2+IF(I16="Y",Settings!$B$3,0),2)
A17: 16 | B17: التأسيس | C17: عربي | D17: 2 | E17: 1 | F17: 2027 | G17: المتميزون | H17: كتاب | I17: Y | J17: library\Grade_02\التأسيس - عربي - الصف الثاني الابتدائي - الترم الأول - 2027 - المتميزون.pdf | K17: pdf | L17: 226 | M17: =ROUND(L17*Settings!$B$4,0) | N17: =ROUND(M17*Settings!$B$2+IF(I17="Y",Settings!$B$3,0),2)
A18: 17 | B18: الشاطر | C18: عربي | D18: 2 | E18: 1 | F18: 2027 | G18: المتميزون | H18: كتاب | I18: Y | J18: library\Grade_02\الشاطر - عربي - الصف الثاني الابتدائي - الترم الأول - 2027 - المتميزون.pdf | K18: pdf | L18: 226 | M18: =ROUND(L18*Settings!$B$4,0) | N18: =ROUND(M18*Settings!$B$2+IF(I18="Y",Settings!$B$3,0),2)
A19: 18 | D19: 2 | E19: 1 | F19: 2027 | H19: كتاب | I19: Y | J19: library\Grade_02\الصف الثاني الابتدائي - الترم الأول - 2027 - قواعد النحو والاملاء للصف الثاني الابتدائي.pdf | K19: pdf | L19: 38 | M19: =ROUND(L19*Settings!$B$4,0) | N19: =ROUND(M19*Settings!$B$2+IF(I19="Y",Settings!$B$3,0),2)
A20: 19 | B20: سلاح التلميذ | D20: 2 | E20: 1 | F20: 2027 | G20: المتميزون | H20: كتاب | I20: Y | J20: library\Grade_02\سلاح التلميذ - الصف الثاني الابتدائي - الترم الأول - 2027 - المتميزون - دين.pdf | K20: pdf | L20: 130 | M20: =ROUND(L20*Settings!$B$4,0) | N20: =ROUND(M20*Settings!$B$2+IF(I20="Y",Settings!$B$3,0),2)
A21: 20 | B21: سلاح التلميذ | C21: انجليزي | D21: 2 | E21: 1 | F21: 2027 | G21: المتميزون | H21: كتاب | I21: Y | J21: library\Grade_02\سلاح التلميذ - انجليزي - الصف الثاني الابتدائي - الترم الأول - 2027 - المتميزون.pdf | K21: pdf | L21: 274 | M21: =ROUND(L21*Settings!$B$4,0) | N21: =ROUND(M21*Settings!$B$2+IF(I21="Y",Settings!$B$3,0),2)
A22: 21 | B22: سلاح التلميذ | C22: رياضيات | D22: 2 | E22: 1 | F22: 2027 | G22: المتميزون | H22: كتاب | I22: Y | J22: library\Grade_02\سلاح التلميذ - رياضيات - الصف الثاني الابتدائي - الترم الأول - 2027 - المتميزون.pdf | K22: pdf | L22: 274 | M22: =ROUND(L22*Settings!$B$4,0) | N22: =ROUND(M22*Settings!$B$2+IF(I22="Y",Settings!$B$3,0),2)
A23: 22 | B23: سلاح التلميذ | C23: عربي | D23: 2 | E23: 1 | F23: 2027 | G23: المتميزون | H23: كتاب | I23: Y | J23: library\Grade_02\سلاح التلميذ - عربي - الصف الثاني الابتدائي - الترم الأول - 2027 - المتميزون.pdf | K23: pdf | L23: 258 | M23: =ROUND(L23*Settings!$B$4,0) | N23: =ROUND(M23*Settings!$B$2+IF(I23="Y",Settings!$B$3,0),2)
A24: 23 | C24: عربي | D24: 2 | E24: 1 | F24: 2027 | G24: المتميزون | H24: كتاب | I24: Y | J24: library\Grade_02\عربي - الصف الثاني الابتدائي - الترم الأول - 2027 - المتميزون - الاستاذ.pdf | K24: pdf | L24: 414 | M24: =ROUND(L24*Settings!$B$4,0) | N24: =ROUND(M24*Settings!$B$2+IF(I24="Y",Settings!$B$3,0),2)
A25: 24 | C25: عربي | D25: 2 | E25: 1 | F25: 2027 | G25: المتميزون | H25: كتاب | I25: Y | J25: library\Grade_02\عربي - الصف الثاني الابتدائي - الترم الأول - 2027 - المتميزون - قطر.pdf | K25: pdf | L25: 266 | M25: =ROUND(L25*Settings!$B$4,0) | N25: =ROUND(M25*Settings!$B$2+IF(I25="Y",Settings!$B$3,0),2)
A26: 25 | C26: عربي | D26: 2 | E26: 1 | H26: كتاب | I26: Y | J26: library\Grade_02\عربي - الصف الثاني الابتدائي - الترم الأول - بوكليت منهج اللغه ال ه للصف الثاني الابتدائي.pdf | K26: pdf | L26: 49 | M26: =ROUND(L26*Settings!$B$4,0) | N26: =ROUND(M26*Settings!$B$2+IF(I26="Y",Settings!$B$3,0),2)
A27: 26 | B27: قطر الندى | D27: 2 | E27: 1 | F27: 2027 | G27: المتميزون | H27: كتاب | I27: Y | J27: library\Grade_02\قطر الندى - الصف الثاني الابتدائي - الترم الأول - 2027 - المتميزون - دين.pdf | K27: pdf | L27: 106 | M27: =ROUND(L27*Settings!$B$4,0) | N27: =ROUND(M27*Settings!$B$2+IF(I27="Y",Settings!$B$3,0),2)
A28: 27 | B28: قطر الندى | C28: رياضيات | D28: 2 | E28: 1 | F28: 2027 | H28: كتاب | I28: Y | J28: library\Grade_02\قطر الندى - رياضيات - الصف الثاني الابتدائي - الترم الأول - 2027.pdf | K28: pdf | L28: 282 | M28: =ROUND(L28*Settings!$B$4,0) | N28: =ROUND(M28*Settings!$B$2+IF(I28="Y",Settings!$B$3,0),2)
A29: 28 | B29: التأسيس | C29: عربي | D29: 2 | E29: 1 | F29: 2027 | G29: المتميزون | H29: ملحق | I29: Y | J29: library\Grade_02\ملحق التأسيس - عربي - الصف الثاني الابتدائي - الترم الأول - 2027 - المتميزون.pdf | K29: pdf | L29: 50 | M29: =ROUND(L29*Settings!$B$4,0) | N29: =ROUND(M29*Settings!$B$2+IF(I29="Y",Settings!$B$3,0),2)
A30: 29 | C30: عربي | D30: 2 | E30: 1 | F30: 2027 | G30: المتميزون | H30: ملحق | I30: Y | J30: library\Grade_02\ملحق عربي - الصف الثاني الابتدائي - الترم الأول - 2027 - المتميزون - الاستاذ.pdf | K30: pdf | L30: 99 | M30: =ROUND(L30*Settings!$B$4,0) | N30: =ROUND(M30*Settings!$B$2+IF(I30="Y",Settings!$B$3,0),2)
A31: 30 | B31: الاضواء | C31: رياضيات | D31: 3 | E31: 1 | F31: 2027 | G31: المتميزون | H31: كتاب | I31: Y | J31: library\Grade_03\الاضواء - رياضيات - الصف الثالث الابتدائي - الترم الأول - 2027 - المتميزون.pdf | K31: pdf | L31: 216 | M31: =ROUND(L31*Settings!$B$4,0) | N31: =ROUND(M31*Settings!$B$2+IF(I31="Y",Settings!$B$3,0),2)
A32: 31 | B32: الاضواء | C32: عربي | D32: 3 | E32: 1 | F32: 2027 | G32: المتميزون | H32: كتاب | I32: Y | J32: library\Grade_03\الاضواء - عربي - الصف الثالث الابتدائي - الترم الأول - 2027 - المتميزون.pdf | K32: pdf | L32: 242 | M32: =ROUND(L32*Settings!$B$4,0) | N32: =ROUND(M32*Settings!$B$2+IF(I32="Y",Settings!$B$3,0),2)
A33: 32 | B33: الاضواء | C33: عربي | D33: 3 | E33: 1 | F33: 2027 | H33: كتاب | I33: Y | J33: library\Grade_03\الاضواء - عربي - الصف الثالث الابتدائي - الترم الأول - 2027.pdf | K33: pdf | L33: 99 | M33: =ROUND(L33*Settings!$B$4,0) | N33: =ROUND(M33*Settings!$B$2+IF(I33="Y",Settings!$B$3,0),2)
A34: 33 | B34: التأسيس | C34: رياضيات | D34: 3 | E34: 1 | F34: 2027 | H34: كتاب | I34: Y | J34: library\Grade_03\التأسيس - رياضيات - الصف الثالث الابتدائي - الترم الأول - 2027.pdf | K34: pdf | L34: 258 | M34: =ROUND(L34*Settings!$B$4,0) | N34: =ROUND(M34*Settings!$B$2+IF(I34="Y",Settings!$B$3,0),2)
A35: 34 | B35: التأسيس | C35: عربي | D35: 3 | E35: 1 | F35: 2027 | G35: المتميزون | H35: كتاب | I35: Y | J35: library\Grade_03\التأسيس - عربي - الصف الثالث الابتدائي - الترم الأول - 2027 - المتميزون.pdf | K35: pdf | L35: 242 | M35: =ROUND(L35*Settings!$B$4,0) | N35: =ROUND(M35*Settings!$B$2+IF(I35="Y",Settings!$B$3,0),2)
A36: 35 | D36: 3 | E36: 1 | F36: 2027 | H36: كتاب | I36: Y | J36: library\Grade_03\الصف الثالث الابتدائي - الترم الأول - 2027 - رياضه.pdf | K36: pdf | L36: 118 | M36: =ROUND(L36*Settings!$B$4,0) | N36: =ROUND(M36*Settings!$B$2+IF(I36="Y",Settings!$B$3,0),2)
A37: 36 | B37: المعاصر | C37: انجليزي | D37: 3 | E37: 1 | F37: 2027 | G37: المتميزون | H37: كتاب | I37: Y | J37: library\Grade_03\المعاصر - انجليزي - الصف الثالث الابتدائي - الترم الأول - 2027 - المتميزون.pdf | K37: pdf | L37: 298 | M37: =ROUND(L37*Settings!$B$4,0) | N37: =ROUND(M37*Settings!$B$2+IF(I37="Y",Settings!$B$3,0),2)
A38: 37 | B38: جيم | D38: 3 | E38: 1 | F38: 2027 | G38: المتميزون | H38: كتاب | I38: Y | J38: library\Grade_03\جيم - الصف الثالث الابتدائي - الترم الأول - 2027 - المتميزون.pdf | K38: pdf | L38: 266 | M38: =ROUND(L38*Settings!$B$4,0) | N38: =ROUND(M38*Settings!$B$2+IF(I38="Y",Settings!$B$3,0),2)
A39: 38 | B39: سلاح التلميذ | D39: 3 | E39: 1 | F39: 2027 | G39: المتميزون | H39: كتاب | I39: Y | J39: library\Grade_03\سلاح التلميذ - الصف الثالث الابتدائي - الترم الأول - 2027 - المتميزون - دين.pdf | K39: pdf | L39: 162 | M39: =ROUND(L39*Settings!$B$4,0) | N39: =ROUND(M39*Settings!$B$2+IF(I39="Y",Settings!$B$3,0),2)
A40: 39 | B40: سلاح التلميذ | C40: انجليزي | D40: 3 | E40: 1 | F40: 2027 | G40: المتميزون | H40: كتاب | I40: Y | J40: library\Grade_03\سلاح التلميذ - انجليزي - الصف الثالث الابتدائي - الترم الأول - 2027 - المتميزون.pdf | K40: pdf | L40: 288 | M40: =ROUND(L40*Settings!$B$4,0) | N40: =ROUND(M40*Settings!$B$2+IF(I40="Y",Settings!$B$3,0),2)
...

Sheet Settings
A1: Setting | B1: Value | C1: Note
A2: price_per_paper | B2: 0.65 | C2: EGP per printed paper
A3: cover_cost | B3: 20 | C3: EGP added to a book when Cover = Y
A4: pages_per_paper | B4: 0.5 | C4: 1 = single-sided, 0.5 = double-sided
A5: default_cover | B5: Y | C5: Y = new books include a cover by default
A6: price_formula | B6: (PaperCount * price_per_paper) + IF(Cover='Y', cover_cost, 0) | C6: Unit Price column uses this
